Workbook

Sheet 120180 MVA Transformer
B2: Supplier Feedback - 120/180 MVA Transformer
B3: Dealer | C3: Manufacturer | D3: Lead Time (wks) | E3: Estimated Cost | F3: Estimated Delivery | G3: Production Slot Purchasing? | H3: Additional Notes
B4: Power Asset Recovery Corp. | F4: =IF(D4="","",TODAY()+D4*7+30) | H4: Searching
B5: Mars Transformers | D5: 76 | F5: =IF(D5="","",TODAY()+D5*7+30) -> 46638 | H5: Recommended 13.8kv on Secondary Side
B6: Virginia Transformer | D6: 56 | F6: =IF(D6="","",TODAY()+D6*7+30) -> 46498
B7: Sunbelt | F7: =IF(D7="","",TODAY()+D7*7+30) | H7: No Quote - Can't Find Anything
F8: =IF(D8="","",TODAY()+D8*7+30)
F9: =IF(D9="","",TODAY()+D9*7+30)
F10: =IF(D10="","",TODAY()+D10*7+30)
F11: =IF(D11="","",TODAY()+D11*7+30)
F12: =IF(D12="","",TODAY()+D12*7+30)
F13: =IF(D13="","",TODAY()+D13*7+30)
F14: =IF(D14="","",TODAY()+D14*7+30)
F15: =IF(D15="","",TODAY()+D15*7+30)
B17: Option 1
B18: 120/160/200//224 MVA 138kv Delta - 34.5kv Grounded Wye Secondary
B19: Option 2
B20: 180/240/300//336 MVA 138kv Delta - 34.5kv Grounded Wye Secondary

Sheet PV Fiberlight
B1: Option 1 | C1: Option 2 | D1: Option 3 | E1: Option 4 | G1: Rate (annual)
A2: Upfront | B2: 250000 | C2: 125000 | D2: 65000 | E2: 0 | G2: 0.1
A3: 60 Months (Monthly Payment) | B3: 3750 | C3: 9250 | D3: 12650 | E3: =15500 -> 15500 | G3: Rate (monthly)
A4: Total | B4: =B2+(B3*60) -> 475000 | C4: =C2+(C3*60) -> 680000 | D4: =D2+(D3*60) -> 824000 | E4: =E2+(E3*60) -> 930000 | G4: =(1+G2)^(1/12)-1 -> 0.0079741404
A7: PV of Monthly | B7: =B3*(1-(1/(1+$G$4)^60))/$G$4 -> 178269.38 | C7: =C3*(1-(1/(1+$G$4)^60))/$G$4 -> 439731.13 | D7: =D3*(1-(1/(1+$G$4)^60))/$G$4 -> 601362.03 | E7: =E3*(1-(1/(1+$G$4)^60))/$G$4 -> 736846.75
A8: Total PV | B8: =B7+B2 -> 428269.38 | C8: =C7+C2 -> 564731.13 | D8: =D7+D2 -> 666362.03 | E8: =E7+E2 -> 736846.75

Sheet Summary
B1: Container | C1: Miner Type | D1: Status | E1: Miner Capacity | F1: Miner Manufacturer | G1: Phase | H1: Feeder Name | I1: Switch # | J1: High Voltage | K1: XF # | L1: XF SN | M1: XF Manufacturer | N1: XF KvA | O1: Fluid Type | P1: Container Manufacturer | Q1: Notes
B2: *TP01 | C2: Mara T2 | D2: Deployed | E2: 160 | F2: Bitmain | G2: 0 | H2: 1A | I2: SW001-A | J2: 6.9KV | K2: XF000 | L2: 2301102024 | M2: CIE | N2: 2550 | O2: OIL | P2: Fbox
B3: *TP02 | C3: Whatsminer M63S | D3: Energized | E3: --- | F3: MicroBT | G3: 0 | H3: 1A | I3: SW001-A | J3: 6.9KV | K3: ***** | L3: ********** | M3: ********** | N3: ***** | P3: Hydro | Q3: Hash House
B4: C000 | C4: Mara T2 | D4: Deployed | E4: 160 | F4: Bitmain | G4: 0 | H4: 1A | I4: SW001-A | J4: 6.9KV | K4: XF001 | L4: N/A | M4: N/A | N4: N/A | O4: N/A | P4: Fbox
B5: C001 | C5: Teraflux AI3680 | D5: Deployed | E5: 128 | F5: Auradine | G5: 0 | H5: 1A | I5: SW001-A | J5: 6.9KV | K5: ***** | L5: ********** | M5: ********** | N5: ***** | P5: Submer
B6: C002 | C6: Teraflux AI3680 | D6: Deployed | E6: 128 | F6: Auradine | G6: 0 | H6: 1A | I6: SW001-A | J6: 6.9KV | K6: XF002 | L6: ST1121-353957 | M6: Sunbelt | N6: 2000 | O6: OIL | P6: Submer
B7: C003 | C7: BixBit Hydro | D7: Offline | E7: 0 | G7: 0 | H7: 1A | I7: SW001-A | J7: 6.9KV | K7: ***** | L7: ********** | M7: ********** | N7: ***** | P7: Hydro
B8: C004 | C8: Whatsminer M56S++ | D8: Deployed | E8: 128 | F8: MicroBT | G8: 1 | H8: 11A | I8: SW002-A | J8: 34.5KV | K8: XF003 | L8: 2406041 | M8: Jiangsu Dabbojin | N8: 2600 | O8: FR3 | P8: Fbox
B9: C005 | C9: Whatsminer M56S++ | D9: Deployed | E9: 128 | F9: MicroBT | G9: 1 | H9: 11A | I9: SW002-A | J9: 34.5KV | K9: ***** | L9: ********** | M9: ********** | N9: ***** | P9: Fbox
B10: C006 | C10: Whatsminer M56S++ | D10: Deployed | E10: 128 | F10: MicroBT | G10: 1 | H10: 11A | I10: SW002-B | J10: 34.5KV | K10: XF004 | L10: 2406040 | M10: Jiangsu Dabbojin | N10: 2600 | O10: FR3 | P10: Fbox
B11: C007 | C11: Whatsminer M56S++ | D11: Deployed | E11: 128 | F11: MicroBT | G11: 1 | H11: 11A | I11: SW002-B | J11: 34.5KV | K11: ***** | L11: ********** | M11: ********** | N11: ***** | P11: Fbox
B12: C008 | C12: Whatsminer M56S++ | D12: Deployed | E12: 128 | F12: MicroBT | G12: 1 | H12: 11A | I12: SW002-B | J12: 34.5KV | K12: XF005 | L12: 2406072 | M12: Jiangsu Dabbojin | N12: 2600 | O12: FR3 | P12: Fbox
B13: C009 | C13: Whatsminer M56S++ | D13: Deployed | E13: 128 | F13: MicroBT | G13: 1 | H13: 11A | I13: SW002-B | J13: 34.5KV | K13: ***** | L13: ********** | M13: ********** | N13: ***** | P13: Fbox
B14: C010 | C14: Whatsminer M56S++ | D14: Deployed | E14: 128 | F14: MicroBT | G14: 1+ | H14: 11B | I14: SW003-A | J14: 34.5KV | K14: XF006 | L14: JC 2800-2415 | M14: JCL Energy | N14: 2600 | O14: OIL | P14: Fbox
B15: C011 | C15: Whatsminer M56S++ | D15: Deployed | E15: 128 | F15: MicroBT | G15: 1+ | H15: 11B | I15: SW003-A | J15: 34.5KV | K15: ***** | L15: ********** | M15: ********** | N15: ***** | P15: Fbox
B16: C012 | C16: Whatsminer M56S++ | D16: Deployed | E16: 128 | F16: MicroBT | G16: 1+ | H16: 11B | I16: SW003-A | J16: 34.5KV | K16: XF007 | L16: JC2600-2418 | M16: JCL Energy | N16: 2600 | O16: OIL | P16: Fbox
B17: C013 | C17: Whatsminer M66S | D17: Deployed | E17: 128 | F17: MicroBT | G17: 1+ | H17: 11B | I17: SW003-A | J17: 34.5KV | K17: ***** | L17: ********** | M17: ********** | N17: ***** | P17: Fbox
B18: C014 | C18: Greenhash Hydro | D18: Energized | E18: 0 | G18: 0 | H18: 1B | I18: SW001-B | J18: 6.9KV | K18: XF008 | L18: ST1121-353953 | M18: Sunbelt | N18: 2000 | O18: FR3 | P18: Hydro
B19: C015 | C19: Fog Hashing Hydro | D19: Energized | E19: 0 | G19: 0 | H19: 1B | I19: SW001-B | J19: 6.9KV | K19: ***** | L19: ********** | M19: ********** | N19: ***** | P19: Hydro
B20: C016 | C20: Fbox Hydro | D20: Deployed | E20: 0 | G20: 0 | H20: 2A | I20: SW001-C | J20: 6.9KV | K20: XF009 | L20: ST1121-353951 | M20: Sunbelt | N20: 2000 | O20: FR3 | P20: Hydro
B21: C017 | C21: Antminer S21 | D21: Deployed | E21: 160 | F21: Bitmain | G21: 0 | H21: 2A | I21: SW001-C | J21: 6.9KV | K21: ***** | L21: ********** | M21: ********** | N21: ***** | P21: Fbox
B22: C018 | C22: Whatsminer M56S++ | D22: Deployed | E22: 128 | F22: MicroBT | G22: 1 | H22: 11A | I22: SW002-A | J22: 34.5KV | K22: XF010 | L22: 2406081 | M22: Jiangsu Dabbojin | N22: 2600 | O22: FR3 | P22: Fbox
B23: C019 | C23: Whatsminer M56S++ | D23: Deployed | E23: 128 | F23: MicroBT | G23: 1 | H23: 11A | I23: SW002-A | J23: 34.5KV | K23: ***** | L23: ********** | M23: ********** | N23: ***** | P23: Fbox
B24: C020 | C24: Whatsminer M56S++ | D24: Deployed | E24: 128 | F24: MicroBT | G24: 1 | H24: 11A | I24: SW002-B | J24: 34.5KV | K24: XF011 | L24: 2406094 | M24: Jiangsu Dabbojin | N24: 2600 | O24: FR3 | P24: Fbox
B25: C021 | C25: Whatsminer M56S++ | D25: Deployed | E25: 128 | F25: MicroBT | G25: 1 | H25: 11A | I25: SW002-B | J25: 34.5KV | K25: ***** | L25: ********** | M25: ********** | N25: ***** | P25: Fbox
B26: C022 | C26: Whatsminer M56S++ | D26: Deployed | E26: 128 | F26: MicroBT | G26: 1 | H26: 11A | I26: SW002-B | J26: 34.5KV | K26: XF012 | L26: 2406093 | M26: Jiangsu Dabbojin | N26: 2600 | O26: FR3 | P26: Fbox
B27: C023 | C27: Whatsminer M56S++ | D27: Deployed | E27: 128 | F27: MicroBT | G27: 1 | H27: 11A | I27: SW002-B | J27: 34.5KV | K27: ***** | L27: ********** | M27: ********** | N27: ***** | P27: Fbox
B28: C024 | C28: Whatsminer M56S++ | D28: Deployed | E28: 128 | F28: MicroBT | G28: 1+ | H28: 11B | I28: SW003-A | J28: 34.5KV | K28: XF013 | L28: JC2600-2413 | M28: JCL Energy | N28: 2600 | O28: OIL | P28: Fbox
B29: C025 | C29: Whatsminer M56S++ | D29: Deployed | E29: 128 | F29: MicroBT | G29: 1+ | H29: 11B | I29: SW003-A | J29: 34.5KV | K29: ***** | L29: ********** | M29: ********** | N29: ***** | P29: Fbox
B30: C026 | C30: Whatsminer M56S++ | D30: Deployed | E30: 128 | F30: MicroBT | G30: 1+ | H30: 11B | I30: SW003-A | J30: 34.5KV | K30: XF014 | L30: JC2600-2416 | M30: JCL Energy | N30: 2600 | O30: OIL | P30: Fbox
B31: C027 | C31: Whatsminer M56S++ | D31: Deployed | E31: 128 | F31: MicroBT | G31: 1+ | H31: 11B | I31: SW003-A | J31: 34.5KV | K31: ***** | L31: ********** | M31: ********** | N31: ***** | P31: Fbox
B32: C028 | C32: Antminer S21 | D32: Deployed | E32: 160 | F32: Bitmain | G32: 0 | H32: 1B | I32: SW001-B | J32: 6.9KV | K32: XF015 | L32: ST1121-353960 | M32: Sunbelt | N32: 2000 | O32: FR3 | P32: Fbox
B33: C029 | C33: Antminer S21 | D33: Deployed | E33: 160 | F33: Bitmain | G33: 0 | H33: 1B | I33: SW001-B | J33: 6.9KV | K33: ***** | L33: ********** | M33: ********** | N33: ***** | P33: Fbox
B34: C030 | C34: Antminer S21 | D34: Deployed | E34: 160 | F34: Bitmain | G34: 0 | H34: 2A | I34: SW001-C | J34: 6.9KV | K34: XF016 | L34: ST1121-353962 | M34: Sunbelt | N34: 2000 | O34: FR3 | P34: Fbox
B35: C031 | C35: Antminer S21 | D35: Deployed | E35: 160 | F35: Bitmain | G35: 0 | H35: 2A | I35: SW001-C | J35: 6.9KV | K35: ***** | L35: ********** | M35: ********** | N35: ***** | P35: Fbox
B36: C032 | C36: Whatsminer M56S++ | D36: Deployed | E36: 128 | F36: MicroBT | G36: 1 | H36: 11A | I36: SW002-A | J36: 34.5KV | K36: XF017 | L36: 2406097 | M36: Jiangsu Dabbojin | N36: 2600 | O36: FR3 | P36: Fbox
B37: C033 | C37: Whatsminer M56S++ | D37: Deployed | E37: 128 | F37: MicroBT | G37: 1 | H37: 11A | I37: SW002-A | J37: 34.5KV | K37: ***** | L37: ********** | M37: ********** | N37: ***** | P37: Fbox
B38: C034 | C38: Whatsminer M56S++ | D38: Deployed | E38: 128 | F38: MicroBT | G38: 1 | H38: 11A | I38: SW002-B | J38: 34.5KV | K38: XF018 | L38: 2406080 | M38: Jiangsu Dabbojin | N38: 2600 | O38: FR3 | P38: Fbox
B39: C035 | C39: Whatsminer M56S++ | D39: Deployed | E39: 128 | F39: MicroBT | G39: 1 | H39: 11A | I39: SW002-B | J39: 34.5KV | K39: ***** | L39: ********** | M39: ********** | N39: ***** | P39: Fbox
B40: C036 | C40: Whatsminer M56S++ | D40: Deployed | E40: 128 | F40: MicroBT | G40: 1 | H40: 11A | I40: SW002-B | J40: 34.5KV | K40: XF019 | L40: 2406046 | M40: Jiangsu Dabbojin | N40: 2600 | O40: FR3 | P40: Fbox
...

Sheet IP Ranges - Air
A1: Miner Type | B1: Container | C1: Group A | D1: Group B | E1: Group C | F1: Group D
A2: =_xlfn.XLOOKUP(B2,Summary!B:B,Summary!C:C,"") -> Whatsminer M60S | B2: C188 | C2: 10.31.0 | D2: 10.31.1 | E2: 10.31.2 | F2: 10.31.3 | I2: =H2&".0-255" -> .0-255
A3: =_xlfn.XLOOKUP(B3,Summary!B:B,Summary!C:C,"") -> Whatsminer M60S | B3: C209 | C3: 10.31.4 | D3: 10.31.5 | E3: 10.31.6 | F3: 10.31.7 | I3: =H3&".0-255" -> .0-255
A4: =_xlfn.XLOOKUP(B4,Summary!B:B,Summary!C:C,"") -> Empty | B4: C210 | C4: 10.31.8 | D4: 10.31.9 | E4: 10.31.10 | F4: 10.31.11 | I4: =H4&".0-255" -> .0-255
A5: =_xlfn.XLOOKUP(B5,Summary!B:B,Summary!C:C,"") -> Whatsminer M60S | B5: C223 | C5: 10.31.12 | D5: 10.31.13 | E5: 10.31.14 | F5: 10.31.15 | I5: =H5&".0-255" -> .0-255
A6: =_xlfn.XLOOKUP(B6,Summary!B:B,Summary!C:C,"") -> Whatsminer M60S | B6: C224 | C6: 10.31.16 | D6: 10.31.17 | E6: 10.31.18 | F6: 10.31.19 | I6: =H6&".0-255" -> .0-255
A7: =_xlfn.XLOOKUP(B7,Summary!B:B,Summary!C:C,"") -> Empty | B7: C225 | C7: 10.31.20 | D7: 10.31.21 | E7: 10.31.22 | F7: 10.31.23 | I7: =H7&".0-255" -> .0-255
A8: =_xlfn.XLOOKUP(B8,Summary!B:B,Summary!C:C,"") -> Whatsminer M60S | B8: C226 | C8: 10.31.24 | D8: 10.31.25 | E8: 10.31.26 | F8: 10.31.27 | I8: =H8&".0-255" -> .0-255
A9: =_xlfn.XLOOKUP(B9,Summary!B:B,Summary!C:C,"") -> Whatsminer M60 | B9: C239 | C9: 10.31.28 | D9: 10.31.29 | E9: 10.31.30 | F9: 10.31.31 | I9: =H9&".0-255" -> .0-255
A10: =_xlfn.XLOOKUP(B10,Summary!B:B,Summary!C:C,"") -> Empty | B10: C240 | C10: 10.31.32 | D10: 10.31.33 | E10: 10.31.34 | F10: 10.31.35 | I10: =H10&".0-255" -> .0-255
A11: =_xlfn.XLOOKUP(B11,Summary!B:B,Summary!C:C,"") -> Whatsminer M60S | B11: C241 | C11: 10.31.36 | D11: 10.31.37 | E11: 10.31.38 | F11: 10.31.39 | I11: =H11&".0-255" -> .0-255
A12: =_xlfn.XLOOKUP(B12,Summary!B:B,Summary!C:C,"") -> Whatsminer M60S | B12: C242 | C12: 10.31.40 | D12: 10.31.41 | E12: 10.31.42 | F12: 10.31.43 | I12: =H12&".0-255" -> .0-255
A13: =_xlfn.XLOOKUP(B13,Summary!B:B,Summary!C:C,"") -> Empty | B13: C243 | C13: 10.31.44 | D13: 10.31.45 | E13: 10.31.46 | F13: 10.31.47 | I13: =H13&".0-255" -> .0-255
... A54: =_xlfn.XLOOKUP(B54,Summary!B:B,Summary!C:C,"") -> Whatsminer M60 / M60S | B54: C284 | C54: 10.31.208 | D54: 10.31.209 | E54: 10.31.210 | F54: 10.31.211 | I54: =H54&".0-255" -> .0-255
I55: =H55&".0-255" -> .0-255
I56: =H56&".0-255" -> .0-255
I57: =H57&".0-255" -> .0-255
I58: =H58&".0-255" -> .0-255
I59: =H59&".0-255" -> .0-255
I60: =H60&".0-255" -> .0-255
I61: =H61&".0-255" -> .0-255
I62: =H62&".0-255" -> .0-255
I63: =H63&".0-255" -> .0-255
I64: =H64&".0-255" -> .0-255
I65: =H65&".0-255" -> .0-255
I66: =H66&".0-255" -> .0-255
... I332: =H332&".0-255" -> .0-255

Sheet IP Ranges - Immersion
A1: Miner Type | B1: Container | C1: Main Switch | D1: Tank 1 | E1: Tank 2 | F1: Tank 3 | G1: Tank 4 | H1: Tank 5 | I1: Tank 6 | J1: Tank 7 | K1: Tank 8 | L1: Phase | M1: LEGEND | P1: Power Target | Q1: Stock Power
A2: =_xlfn.XLOOKUP(B2,Summary!B:B,Summary!C:C,"") -> Mara T2 | B2: *TP01 | C2: 10.21.255.186 | D2: 10.29.11.0 | E2: 10.29.12.0 | F2: 10.29.13.0 | G2: 10.29.14.0 | H2: 10.29.15.0 | I2: 10.29.16.0 | J2: 10.29.17.0 | K2: 10.29.18.0 | L2: =_xlfn.XLOOKUP(B2,Summary!B:B,Summary!G:G) -> 0
A3: =_xlfn.XLOOKUP(B3,Summary!B:B,Summary!C:C,"") -> Whatsminer M63S | B3: *TP02 | D3: 10.21.227.0 | L3: =_xlfn.XLOOKUP(B3,Summary!B:B,Summary!G:G) -> 0
A4: =_xlfn.XLOOKUP(B4,Summary!B:B,Summary!C:C,"") -> Mara T2 | B4: C000 | C4: 10.21.255.0 | D4: 10.21.221.0 | E4: --- | F4: --- | G4: ---| | H4: 10.21.222.0 | I4: --- | J4: --- | K4: ---| | L4: =_xlfn.XLOOKUP(B4,Summary!B:B,Summary!G:G) -> 0
A5: =_xlfn.XLOOKUP(B5,Summary!B:B,Summary!C:C,"") -> Teraflux AI3680 | B5: C001 | C5: 10.21.255.1 | D5: 10.21.11.0 | E5: --- | F5: --- | G5: ---| | H5: 10.21.12.0 | I5: --- | J5: --- | K5: ---| | L5: =_xlfn.XLOOKUP(B5,Summary!B:B,Summary!G:G) -> 0 | M5: Phase 0 | N5: Pickaxe 2
A6: =_xlfn.XLOOKUP(B6,Summary!B:B,Summary!C:C,"") -> Teraflux AI3680 | B6: C002 | C6: 10.21.255.2 | D6: 10.21.13.0 | E6: --- | F6: --- | G6: ---| | H6: 10.21.14.0 | I6: --- | J6: --- | K6: ---| | L6: =_xlfn.XLOOKUP(B6,Summary!B:B,Summary!G:G) -> 0 | M6: Phase 1 | N6: Pickaxe 2
A7: =_xlfn.XLOOKUP(B7,Summary!B:B,Summary!C:C,"") -> BixBit Hydro | B7: C003 | C7: 10.21.255.3 | D7: 10.21.15.0 | E7: --- | F7: --- | G7: ---| | H7: 10.21.16.0 | I7: --- | J7: --- | K7: ---| | L7: =_xlfn.XLOOKUP(B7,Summary!B:B,Summary!G:G) -> 0 | M7: Phase 1+ | N7: Pickaxe 2
A8: =_xlfn.XLOOKUP(B8,Summary!B:B,Summary!C:C,"") -> Whatsminer M56S++ | B8: C004 | C8: 10.21.255.4 | D8: 10.21.17.0 | E8: --- | F8: --- | G8: ---| | H8: 10.21.18.0 | I8: --- | J8: --- | K8: ---| | L8: =_xlfn.XLOOKUP(B8,Summary!B:B,Summary!G:G) -> 1 | M8: Phase 2 | N8: Pickaxe 2 | P8: Stock | Q8: 5700W
A9: =_xlfn.XLOOKUP(B9,Summary!B:B,Summary!C:C,"") -> Whatsminer M56S++ | B9: C005 | C9: 10.21.255.5 | D9: 10.21.51.0 | E9: 10.21.52.0 | F9: 10.21.53.0 | G9: 10.21.54.0 | H9: 10.21.55.0 | I9: 10.21.56.0 | J9: 10.21.57.0 | K9: 10.21.58.0 | L9: =_xlfn.XLOOKUP(B9,Summary!B:B,Summary!G:G) -> 1 | M9: Phase 3 | N9: Pickaxe 2 | P9: Stock | Q9: 5700W
A10: =_xlfn.XLOOKUP(B10,Summary!B:B,Summary!C:C,"") -> Whatsminer M56S++ | B10: C006 | C10: 10.21.255.6 | D10: 10.21.61.0 | E10: 10.21.62.0 | F10: 10.21.63.0 | G10: 10.21.64.0 | H10: 10.21.65.0 | I10: 10.21.66.0 | J10: 10.21.67.0 | K10: 10.21.68.0 | L10: =_xlfn.XLOOKUP(B10,Summary!B:B,Summary!G:G) -> 1 | M10: Phase 4 | N10: Pickaxe 3 | P10: Stock | Q10: 5700W
A11: =_xlfn.XLOOKUP(B11,Summary!B:B,Summary!C:C,"") -> Whatsminer M56S++ | B11: C007 | C11: 10.21.255.7 | D11: 10.21.71.0 | E11: 10.21.72.0 | F11: 10.21.73.0 | G11: 10.21.74.0 | H11: 10.21.75.0 | I11: 10.21.76.0 | J11: 10.21.77.0 | K11: 10.21.78.0 | L11: =_xlfn.XLOOKUP(B11,Summary!B:B,Summary!G:G) -> 1 | M11: Phase 5 | N11: Pickaxe 3 | P11: Stock | Q11: 5700W
A12: =_xlfn.XLOOKUP(B12,Summary!B:B,Summary!C:C,"") -> Whatsminer M56S++ | B12: C008 | C12: 10.21.255.8 | D12: 10.21.81.0 | E12: 10.21.82.0 | F12: 10.21.83.0 | G12: 10.21.84.0 | H12: 10.21.85.0 | I12: 10.21.86.0 | J12: 10.21.87.0 | K12: 10.21.88.0 | L12: =_xlfn.XLOOKUP(B12,Summary!B:B,Summary!G:G) -> 1 | M12: Phase 6 | N12: Pickaxe 3 | P12: Stock | Q12: 5700W
A13: =_xlfn.XLOOKUP(B13,Summary!B:B,Summary!C:C,"") -> Whatsminer M56S++ | B13: C009 | C13: 10.21.255.9 | D13: 10.21.91.0 | E13: 10.21.92.0 | F13: 10.21.93.0 | G13: 10.21.94.0 | H13: 10.21.95.0 | I13: 10.21.96.0 | J13: 10.21.97.0 | K13: 10.21.98.0 | L13: =_xlfn.XLOOKUP(B13,Summary!B:B,Summary!G:G) -> 1 | P13: Stock | Q13: 5700W
A14: =_xlfn.XLOOKUP(B14,Summary!B:B,Summary!C:C,"") -> Whatsminer M56S++ | B14: C010 | C14: 10.21.255.10 | D14: 10.21.101.0 | E14: 10.21.102.0 | F14: 10.21.103.0 | G14: 10.21.104.0 | H14: 10.21.105.0 | I14: 10.21.106.0 | J14: 10.21.107.0 | K14: 10.21.108.0 | L14: =_xlfn.XLOOKUP(B14,Summary!B:B,Summary!G:G) -> 1+ | P14: Stock | Q14: 5700W
A15: =_xlfn.XLOOKUP(B15,Summary!B:B,Summary!C:C,"") -> Whatsminer M56S++ | B15: C011 | C15: 10.21.255.11 | D15: 10.21.111.0 | E15: 10.21.112.0 | F15: 10.21.113.0 | G15: 10.21.114.0 | H15: 10.21.115.0 | I15: 10.21.116.0 | J15: 10.21.117.0 | K15: 10.21.118.0 | L15: =_xlfn.XLOOKUP(B15,Summary!B:B,Summary!G:G) -> 1+ | P15: Stock | Q15: 5700W
A16: =_xlfn.XLOOKUP(B16,Summary!B:B,Summary!C:C,"") -> Whatsminer M56S++ | B16: C012 | C16: 10.21.255.12 | D16: 10.21.121.0 | E16: 10.21.122.0 | F16: 10.21.123.0 | G16: 10.21.124.0 | H16: 10.21.125.0 | I16: 10.21.126.0 | J16: 10.21.127.0 | K16: 10.21.128.0 | L16: =_xlfn.XLOOKUP(B16,Summary!B:B,Summary!G:G) -> 1+ | P16: Stock | Q16: 5700W
A17: =_xlfn.XLOOKUP(B17,Summary!B:B,Summary!C:C,"") -> Whatsminer M66S | B17: C013 | C17: 10.21.255.13 | D17: 10.21.41.0 | E17: --- | F17: --- | G17: ---| | H17: 10.21.42.0 | I17: --- | J17: --- | K17: ---| | L17: =_xlfn.XLOOKUP(B17,Summary!B:B,Summary!G:G) -> 1+ | O17: =N17&"-255" -> -255 | P17: Stock | Q17: 5700W
A18: =_xlfn.XLOOKUP(B18,Summary!B:B,Summary!C:C,"") -> Greenhash Hydro | B18: C014 | C18: 10.21.255.14 | D18: 10.21.43.0 | E18: --- | F18: --- | G18: ---| | H18: 10.21.44.0 | I18: --- | J18: --- | K18: ---| | L18: =_xlfn.XLOOKUP(B18,Summary!B:B,Summary!G:G) -> 0 | O18: =N18&"-255" -> -255
A19: =_xlfn.XLOOKUP(B19,Summary!B:B,Summary!C:C,"") -> Fog Hashing Hydro | B19: C015 | C19: 10.21.255.15 | D19: 10.22.21.0 | E19: 10.22.22.0 | F19: 10.22.23.0 | G19: 10.22.24.0 | H19: 10.22.25.0 | I19: 10.22.26.0 | J19: 10.22.27.0 | K19: 10.22.28.0 | L19: =_xlfn.XLOOKUP(B19,Summary!B:B,Summary!G:G) -> 0 | O19: =N19&"-255" -> -255
A20: =_xlfn.XLOOKUP(B20,Summary!B:B,Summary!C:C,"") -> Fbox Hydro | B20: C016 | C20: 10.21.255.16 | D20: 10.22.31.0 | E20: 10.22.32.0 | F20: 10.22.33.0 | G20: 10.22.34.0 | H20: 10.22.35.0 | I20: x | J20: x | K20: x | L20: =_xlfn.XLOOKUP(B20,Summary!B:B,Summary!G:G) -> 0 | O20: =N20&"-255" -> -255 | U20: C016 | V20: 10.21.255.16 | W20: 10.21.47.0 | X20: --- | Y20: --- | Z20: ---| | AA20: 10.21.48.0 | AB20: --- | AC20: --- | AD20: ---|
A21: =_xlfn.XLOOKUP(B21,Summary!B:B,Summary!C:C,"") -> Antminer S21 | B21: C017 | C21: 10.21.255.17 | D21: 10.22.41.0 | E21: 10.22.42.0 | F21: 10.22.43.0 | G21: 10.22.44.0 | H21: 10.22.45.0 | I21: 10.22.46.0 | J21: 10.22.47.0 | K21: 10.22.48.0 | L21: =_xlfn.XLOOKUP(B21,Summary!B:B,Summary!G:G) -> 0 | O21: =N21&"-255" -> -255 | P21: 4800W | Q21: 3800W
A22: =_xlfn.XLOOKUP(B22,Summary!B:B,Summary!C:C,"") -> Whatsminer M56S++ | B22: C018 | C22: 10.21.255.18 | D22: 10.22.51.0 | E22: 10.22.52.0 | F22: 10.22.53.0 | G22: 10.22.54.0 | H22: 10.22.55.0 | I22: 10.22.56.0 | J22: 10.22.57.0 | K22: 10.22.58.0 | L22: =_xlfn.XLOOKUP(B22,Summary!B:B,Summary!G:G) -> 1 | O22: =N22&"-255" -> -255 | P22: Stock | Q22: 5700W
A23: =_xlfn.XLOOKUP(B23,Summary!B:B,Summary!C:C,"") -> Whatsminer M56S++ | B23: C019 | C23: 10.21.255.19 | D23: 10.22.61.0 | E23: 10.22.62.0 | F23: 10.22.63.0 | G23: 10.22.64.0 | H23: 10.22.65.0 | I23: 10.22.66.0 | J23: 10.22.67.0 | K23: 10.22.68.0 | L23: =_xlfn.XLOOKUP(B23,Summary!B:B,Summary!G:G) -> 1 | O23: =N23&"-255" -> -255 | P23: Stock | Q23: 5700W
A24: =_xlfn.XLOOKUP(B24,Summary!B:B,Summary!C:C,"") -> Whatsminer M56S++ | B24: C020 | C24: 10.21.255.20 | D24: 10.22.71.0 | E24: 10.22.72.0 | F24: 10.22.73.0 | G24: 10.22.74.0 | H24: 10.22.75.0 | I24: 10.22.76.0 | J24: 10.22.77.0 | K24: 10.22.78.0 | L24: =_xlfn.XLOOKUP(B24,Summary!B:B,Summary!G:G) -> 1 | O24: =N24&"-255" -> -255 | P24: Stock | Q24: 5700W
A25: =_xlfn.XLOOKUP(B25,Summary!B:B,Summary!C:C,"") -> Whatsminer M56S++ | B25: C021 | C25: 10.21.255.21 | D25: 10.22.81.0 | E25: 10.22.82.0 | F25: 10.22.83.0 | G25: 10.22.84.0 | H25: 10.22.85.0 | I25: 10.22.86.0 | J25: 10.22.87.0 | K25: 10.22.88.0 | L25: =_xlfn.XLOOKUP(B25,Summary!B:B,Summary!G:G) -> 1 | O25: =N25&"-255" -> -255 | P25: Stock | Q25: 5700W
A26: =_xlfn.XLOOKUP(B26,Summary!B:B,Summary!C:C,"") -> Whatsminer M56S++ | B26: C022 | C26: 10.21.255.22 | D26: 10.22.91.0 | E26: 10.22.92.0 | F26: 10.22.93.0 | G26: 10.22.94.0 | H26: 10.22.95.0 | I26: 10.22.96.0 | J26: 10.22.97.0 | K26: 10.22.98.0 | L26: =_xlfn.XLOOKUP(B26,Summary!B:B,Summary!G:G) -> 1 | O26: =N26&"-255" -> -255 | P26: Stock | Q26: 5700W
A27: =_xlfn.XLOOKUP(B27,Summary!B:B,Summary!C:C,"") -> Whatsminer M56S++ | B27: C023 | C27: 10.21.255.23 | D27: 10.22.101.0 | E27: 10.22.102.0 | F27: 10.22.103.0 | G27: 10.22.104.0 | H27: 10.22.105.0 | I27: 10.22.106.0 | J27: 10.22.107.0 | K27: 10.22.108.0 | L27: =_xlfn.XLOOKUP(B27,Summary!B:B,Summary!G:G) -> 1 | O27: =N27&"-255" -> -255 | P27: Stock | Q27: 5700W
A28: =_xlfn.XLOOKUP(B28,Summary!B:B,Summary!C:C,"") -> Whatsminer M56S++ | B28: C024 | C28: 10.21.255.24 | D28: 10.22.111.0 | E28: 10.22.112.0 | F28: 10.22.113.0 | G28: 10.22.114.0 | H28: 10.22.115.0 | I28: 10.22.116.0 | J28: 10.22.117.0 | K28: 10.22.118.0 | L28: =_xlfn.XLOOKUP(B28,Summary!B:B,Summary!G:G) -> 1+ | O28: =N28&"-255" -> -255 | P28: Stock | Q28: 5700W
A29: =_xlfn.XLOOKUP(B29,Summary!B:B,Summary!C:C,"") -> Whatsminer M56S++ | B29: C025 | C29: 10.21.255.25 | D29: 10.22.121.0 | E29: 10.22.122.0 | F29: 10.22.123.0 | G29: 10.22.124.0 | H29: 10.22.125.0 | I29: 10.22.126.0 | J29: 10.22.127.0 | K29: 10.22.128.0 | L29: =_xlfn.XLOOKUP(B29,Summary!B:B,Summary!G:G) -> 1+ | O29: =N29&"-255" -> -255 | P29: Stock | Q29: 5700W
A30: =_xlfn.XLOOKUP(B30,Summary!B:B,Summary!C:C,"") -> Whatsminer M56S++ | B30: C026 | C30: 10.21.255.26 | D30: 10.22.131.0 | E30: 10.22.132.0 | F30: 10.22.133.0 | G30: 10.22.134.0 | H30: 10.22.135.0 | I30: 10.22.136.0 | J30: 10.22.137.0 | K30: 10.22.138.0 | L30: =_xlfn.XLOOKUP(B30,Summary!B:B,Summary!G:G) -> 1+ | O30: =N30&"-255" -> -255 | P30: Stock | Q30: 5700W
A31: =_xlfn.XLOOKUP(B31,Summary!B:B,Summary!C:C,"") -> Whatsminer M56S++ | B31: C027 | C31: 10.21.255.27 | D31: 10.22.141.0 | E31: 10.22.142.0 | F31: 10.22.143.0 | G31: 10.22.144.0 | H31: 10.22.145.0 | I31: 10.22.146.0 | J31: 10.22.147.0 | K31: 10.22.148.0 | L31: =_xlfn.XLOOKUP(B31,Summary!B:B,Summary!G:G) -> 1+ | O31: =N31&"-255" -> -255 | P31: Stock | Q31: 5700W
A32: =_xlfn.XLOOKUP(B32,Summary!B:B,Summary!C:C,"") -> Antminer S21 | B32: C028 | C32: 10.21.255.28 | D32: 10.23.11.0 | E32: 10.23.12.0 | F32: 10.23.13.0 | G32: 10.23.14.0 | H32: 10.23.15.0 | I32: 10.23.16.0 | J32: 10.23.17.0 | K32: 10.23.18.0 | L32: =_xlfn.XLOOKUP(B32,Summary!B:B,Summary!G:G) -> 0 | O32: =N32&"-255" -> -255 | P32: 5000W | Q32: 3800W
... A51: =_xlfn.XLOOKUP(B51,Summary!B:B,Summary!C:C,"") -> Antminer S21 | B51: C047 | C51: 10.21.255.47 | D51: 10.24.61.0 | E51: 10.24.62.0 | F51: 10.24.63.0 | G51: 10.24.64.0 | H51: 10.24.65.0 | I51: 10.24.66.0 | J51: 10.24.67.0 | K51: 10.24.68.0 | L51: =_xlfn.XLOOKUP(B51,Summary!B:B,Summary!G:G) -> 1 | O51: =N51&"-255" -> -255 | P51: Stock | Q51: 3800W
A52: =_xlfn.XLOOKUP(B52,Summary!B:B,Summary!C:C,"") -> TAE BESS | B52: C048 | C52: 10.21.255.48 | D52: 10.24.71.0 | E52: 10.24.72.0 | F52: 10.24.73.0 | G52: 10.24.74.0 | H52: 10.24.75.0 | I52: 10.24.76.0 | J52: 10.24.77.0 | K52: 10.24.78.0 | L52: =_xlfn.XLOOKUP(B52,Summary!B:B,Summary!G:G) -> 1 | O52: =N52&"-255" -> -255
A53: =_xlfn.XLOOKUP(B53,Summary!B:B,Summary!C:C,"") -> Whatsminer M56S++ | B53: C049 | C53: 10.21.255.49 | D53: 10.24.81.0 | E53: 10.24.82.0 | F53: 10.24.83.0 | G53: 10.24.84.0 | H53: 10.24.85.0 | I53: 10.24.86.0 | J53: 10.24.87.0 | K53: 10.24.88.0 | L53: =_xlfn.XLOOKUP(B53,Summary!B:B,Summary!G:G) -> 1 | O53: =N53&"-255" -> -255 | P53: Stock | Q53: 5700W
A54: =_xlfn.XLOOKUP(B54,Summary!B:B,Summary!C:C,"") -> Whatsminer M56S++ | B54: C050 | C54: 10.21.255.50 | D54: 10.24.91.0 | E54: 10.24.92.0 | F54: 10.24.93.0 | G54: 10.24.94.0 | H54: 10.24.95.0 | I54: 10.24.96.0 | J54: 10.24.97.0 | K54: 10.24.98.0 | L54: =_xlfn.XLOOKUP(B54,Summary!B:B,Summary!G:G) -> 1 | O54: =N54&"-255" -> -255 | P54: Stock | Q54: 5700W
A55: =_xlfn.XLOOKUP(B55,Summary!B:B,Summary!C:C,"") -> Whatsminer M56S++ | B55: C051 | C55: 10.21.255.51 | D55: 10.24.101.0 | E55: 10.24.102.0 | F55: 10.24.103.0 | G55: 10.24.104.0 | H55: 10.24.105.0 | I55: 10.24.106.0 | J55: 10.24.107.0 | K55: 10.24.108.0 | L55: =_xlfn.XLOOKUP(B55,Summary!B:B,Summary!G:G) -> 1 | O55: =N55&"-255" -> -255 | P55: Stock | Q55: 5700W
A56: =_xlfn.XLOOKUP(B56,Summary!B:B,Summary!C:C,"") -> Whatsminer M56S++ / M66S | B56: C052 | C56: 10.21.255.52 | D56: 10.24.111.0 | E56: 10.24.112.0 | F56: 10.24.113.0 | G56: 10.24.114.0 | H56: 10.24.115.0 | I56: 10.24.116.0 | J56: 10.24.117.0 | K56: 10.24.118.0 | L56: =_xlfn.XLOOKUP(B56,Summary!B:B,Summary!G:G) -> 1+ | O56: =N56&"-255" -> -255 | P56: Stock | Q56: 5700W
A57: =_xlfn.XLOOKUP(B57,Summary!B:B,Summary!C:C,"") -> Whatsminer M66S | B57: C053 | C57: 10.21.255.53 | D57: 10.24.121.0 | E57: 10.24.122.0 | F57: 10.24.123.0 | G57: 10.24.124.0 | H57: 10.24.125.0 | I57: 10.24.126.0 | J57: 10.24.127.0 | K57: 10.24.128.0 | L57: =_xlfn.XLOOKUP(B57,Summary!B:B,Summary!G:G) -> 1+ | O57: =N57&"-255" -> -255 | P57: Stock | Q57: 5700W
A58: =_xlfn.XLOOKUP(B58,Summary!B:B,Summary!C:C,"") -> Antminer S21 | B58: C054 | C58: 10.21.255.54 | D58: 10.24.131.0 | E58: 10.24.132.0 | F58: 10.24.133.0 | G58: 10.24.134.0 | H58: 10.24.135.0 | I58: 10.24.136.0 | J58: 10.24.137.0 | K58: 10.24.138.0 | L58: =_xlfn.XLOOKUP(B58,Summary!B:B,Summary!G:G) -> 1+ | O58: =N58&"-255" -> -255 | P58: Stock | Q58: 3800W
...

Sheet eGauges
A1: XF # | B1: Containers | C1: SN | D1: Model | E1: IP Address | F1: MAC | G1: eGauge Name | H1: Default Username | I1: Default Password | J1: Custom Name | K1: LAN Username | L1: LAN Password | M1: Configured | N1: Notes
A2: XF000
A3: XF001 | B3: C000 / C001 | C3: 2201121400 | D3: EG4115 | E3: 10.21.10.7 | F3: f8:2f:5b:03:6d:c6 | G3: eGauge76695 | H3: owner | I3: rJv4F6h7 | J3: WH-XF001 | K3: mara | L3: marawh | M3: Yes
A4: XF002 | B4: C002 / C003 | C4: 2201121459 | D4: EG4115 | E4: 10.21.10.71 | F4: f8:2f:5b:03:6d:e2 | G4: eGauge76683 | H4: owner | I4: qYd5i9e4 | J4: WH-XF002 | K4: mara | L4: marawh | M4: Yes
A5: XF003 | B5: C004 / C005 | C5: 2502170489 | D5: EG4015 | E5: 10.21.10.199 | F5: f8:2f:5b:05:05:9a | G5: eGauge103568 | H5: owner | I5: Z9X4ZmAh | J5: WH-XF003 | N5: offline
A6: XF004 | B6: C006 / C007 | C6: 2502170311 | D6: EG4015 | E6: 10.21.60.20 | F6: f8:2f:5b:05:07:32 | G6: eGauge103569 | H6: owner | I6: d7bTpU8w | J6: WH-XF004 | K6: mara | L6: marawh | M6: Yes
A7: XF005 | B7: C008 / C009 | C7: 2502170031 | D7: EG4015 | E7: 10.21.80.20 | F7: f8:2f:5b:05:06:02 | G7: eGauge103574 | H7: owner | I7: y6h3V8iC | J7: WH-XF005 | K7: mara | L7: marawh | M7: Yes
A8: XF006 | B8: C010 / C011 | C8: 2310230190 | D8: EG4015 | E8: 10.21.100.20 | F8: f8:2f:5b:04:d7:3e | G8: eGauge103614 | H8: owner | I8: 2nC2S8g4 | J8: WH-XF006 | K8: mara | L8: marawh | M8: Yes
A9: XF007 | B9: C012 / C013 | C9: 2502170309 | D9: EG4015 | E9: 10.21.120.20 | F9: f8:2f:5b:05:07:2a | G9: eGauge103565 | H9: owner | I9: zGs8GqK8 | J9: WH-XF007 | K9: mara | L9: marawh | M9: Yes
A10: XF008 | B10: C014 / C015 | C10: 2201121018 | D10: EG4115 | E10: 10.10.2.197 | F10: f8:2f:5b:03:6e:36 | G10: eGauge76658 | H10: owner | I10: dG8yN5f4 | J10: WH-XF008 | N10: offline
A11: XF009 | B11: C016 / C017 | C11: 2201121466 | D11: EG4115 | E11: 10.22.40.20 | F11: f8:2f:5b:03:6e:3a | G11: eGauge76649 | H11: owner | I11: Bw4Tk3T4 | J11: WH-XF009 | K11: mara | L11: marawh | M11: Partial | N11: CT Sensor is reading 353KW
A12: XF010 | B12: C018 / C019 | C12: 2502170499 | D12: EG4015 | E12: 10.22.60.20 | F12: f8:2f:5b:05:05:c2 | G12: eGauge103560 | H12: owner | I12: 9Gj3Es8m | J12: WH-XF010 | K12: mara | L12: marawh | M12: Yes
A13: XF011 | B13: C020 / C021 | C13: 2502170192 | D13: EG4015 | E13: 10.22.80.20 | F13: f8:2f:5b:05:06:e6 | G13: eGauge103561 | H13: owner | I13: h9Jo9n3B | J13: WH-XF011 | K13: mara | L13: marawh | M13: Yes
A14: XF012 | B14: C022 / C023 | C14: 2502170194 | D14: EG4015 | E14: 10.22.100.20 | F14: f8:2f:5b:05:08:ee | G14: eGauge103567 | H14: owner | I14: 5s5vR7v8 | J14: WH-XF012 | K14: mara | L14: marawh | M14: Yes
A15: XF013 | B15: C024 / C025 | C15: 2502170206 | D15: EG4015 | E15: 10.22.120.20 | F15: f8:2f:5b:05:07:0e | G15: eGauge103566 | H15: owner | I15: s9J7N2C9 | J15: WH-XF013 | K15: mara | L15: marawh | M15: Yes
A16: XF014 | B16: C026 / C027 | C16: 2502170207 | D16: EG4015 | E16: 10.22.140.20 | F16: f8:2f:5b:05:07:12 | G16: eGauge103585 | H16: owner | I16: N2VoJuZj | J16: WH-XF014 | K16: mara | L16: marawh | M16: Yes
A17: XF015 | B17: C028 / C029 | C17: 2201121458 | D17: EG4115 | E17: 10.23.10.20 | F17: f8:2f:5b:03:62:2e | G17: eGauge76639 | H17: owner | I17: 2aL7X6pU | J17: WH-XF015 | K17: mara | L17: marawh | M17: Yes
A18: XF016 | B18: C030 / C031 | C18: 2201121314 | D18: EG4115 | E18: 10.23.30.20 | F18: f8:2f:5b:03:6d:6e | G18: eGauge76725 | H18: owner | I18: J4Cu2h2Y | J18: WH-XF016 | K18: mara | L18: marawh | M18: Yes | N18: CT Sensor reading 629KW
A19: XF017 | B19: C032 / C033 | C19: 2502170226 | D19: EG4015 | E19: 10.23.50.20 | F19: f8:2f:5b:05:07:ea | G19: eGauge103577 | H19: owner | I19: 4M8UhU3w | J19: WH-XF017 | K19: mara | L19: marawh | M19: Yes
A20: XF018 | B20: C034 / C035 | C20: 2502170408 | D20: EG4015 | E20: 10.23.70.20 | F20: f8:2f:5b:05:07:46 | G20: eGauge103564 | H20: owner | I20: Ge5J8ZaZ | J20: WH-XF018 | K20: mara | L20: marawh | M20: Yes
A21: XF019 | B21: C036 / C037 | C21: 2502170219 | D21: EG4015 | E21: 10.23.90.20 | F21: f8:2f:5b:05:08:e2 | G21: eGauge103573 | H21: owner | I21: 8Rd7Jv6J | J21: WH-XF019 | K21: mara | L21: marawh | M21: Yes
A22: XF020 | B22: C038 / C039 | C22: 2405070570 | D22: EG4015 | E22: 10.23.110.20 | F22: f8:2f:5b:04:db:8e | G22: eGauge101647 | H22: owner | I22: KfFf3jDb | J22: WH-XF020 | K22: mara | L22: marawh | M22: Yes
A23: XF021 | B23: C040 / C041 | C23: 2502170472 | D23: EG4015 | E23: 10.23.130.21 | F23: f8:2f:5b:05:05:86 | G23: eGauge103571 | H23: owner | I23: H2jMc8Tx | J23: WH-XF021 | K23: mara | L23: marawh | M23: Yes
A24: XF022 | B24: C042 / C043 | C24: 2201121500 | D24: EG4115 | E24: 10.24.20.20 | F24: f8:2f:5b:03:6d:ee | G24: eGauge76707 | H24: owner | I24: 3iR9F6e7 | J24: WH-XF022 | K24: mara | L24: marawh | M24: Yes | N24: CT Sensor reading 618KW
A25: XF023 | B25: C044 / C045 | C25: 2201121399 | D25: EG4115 | E25: 10.24.30.20 | F25: f8:2f:5b:03:6d:d2 | G25: eGauge76715 | H25: owner | I25: 7NhH4aLa | J25: WH-XF023 | K25: mara | L25: marawh | M25: Yes
A26: XF024 | B26: C046 / C047 | C26: 2502170246 | D26: EG4015 | E26: 10.24.60.20 | F26: f8:2f:5b:05:07:f2 | G26: eGauge103583 | H26: owner | I26: 5Y9kU6W4 | J26: WH-XF024 | K26: mara | L26: marawh | M26: Yes
A27: XF025 | B27: C049 | C27: 2502170041 | D27: EG4015 | E27: 10.24.80.20 | F27: f8:2f:5b:05:06:1a | G27: eGauge103575 | H27: owner | I27: aJ9s5Bc4 | J27: WH-XF025 | K27: mara | L27: marawh | M27: Yes
A28: XF026 | B28: C050 / C051 | C28: 2502170312 | D28: EG4015 | E28: 10.24.100.20 | F28: f8:2f:5b:05:07:36 | G28: eGauge103563 | H28: owner | I28: WeU6y9Wx | J28: WH-XF026 | K28: mara | L28: marawh | M28: Yes
A29: XF027 | B29: C052 / C053 | C29: 2502170443 | D29: EG4015 | E29: 10.24.120.20 | F29: f8:2f:5b:05:05:52 | G29: eGauge103581 | H29: owner | I29: 5m7VrG6M | J29: WH-XF027 | K29: mara | L29: marawh | M29: Yes
A30: XF028 | B30: C054 / C055 | C30: 2502170498 | D30: EG4015 | E30: 10.24.140.20 | F30: f8:2f:5b:05:05:be | G30: eGauge103076 | H30: owner | I30: 4YuUn3e9 | J30: WH-XF028 | K30: mara | L30: marawh | M30: Yes
A31: XF029 | B31: C056 / C057 | C31: 2502170196 | D31: EG4015 | E31: 10.21.140.20 | F31: f8:2f:5b:05:06:f6 | G31: eGauge103559 | H31: owner | I31: g2wShE8w | J31: WH-XF029 | N31: offline
A32: XF030 | B32: C058 / C059 | C32: 2502170191 | D32: EG4015 | E32: 10.21.160.20 | F32: f8:2f:5b:05:06:e2 | G32: eGauge103562 | H32: owner | I32: N6hFw4bF | J32: WH-XF030 | K32: mara | L32: marawh | M32: Yes
A33: XF031 | B33: C060 / C061 | C33: 2310230184 | D33: EG4015 | E33: 10.22.160.20 | F33: f8:2f:5b:04:d7:4e | G33: eGauge103616 | H33: owner | I33: X5F3X6Zc | J33: WH-XF031 | K33: mara | L33: marawh | M33: Yes
A34: XF032 | B34: C062 / C063 | C34: 2502170464 | D34: EG4015 | E34: 10.22.180.20 | F34: f8:2f:5b:05:05:66 | G34: eGauge103579 | H34: owner | I34: C2f7Vu3b | J34: WH-XF032 | K34: mara | L34: marawh | M34: Yes
A35: XF033 | B35: C064 / C065 | C35: 2502170310 | D35: EG4015 | E35: 10.23.150.20 | F35: f8:2f:5b:05:07:2e | G35: eGauge103570 | H35: owner | I35: TtC9Nw2h | J35: WH-XF033 | K35: mara | L35: marawh | M35: Yes
A36: XF034 | B36: C066 / C067 | C36: 2405070266 | D36: EG4015 | E36: 10.23.170.20 | F36: f8:2f:5b:04:ef:36 | G36: eGauge101609 | H36: owner | I36: a5w9H9Sv | J36: WH-XF034 | K36: mara | L36: marawh | M36: Yes
A37: XF035 | B37: C068 / C069 | C37: 2502170406 | D37: EG4015 | E37: 10.24.160.20 | F37: f8:2f:5b:05:07:3e | G37: eGauge103588 | H37: owner | I37: sM6gZv4E | J37: WH-XF035 | K37: mara | L37: marawh | M37: Yes
A38: XF036 | B38: C070 / C071 | C38: 2502170431 | D38: EG4015 | E38: 10.24.180.20 | F38: f8:2f:5b:05:08:42 | G38: eGauge103582 | H38: owner | I38: Du8N2Ng5 | J38: WH-XF036 | K38: mara | L38: marawh | M38: Yes
A39: XF037 | B39: C072 / C073 | C39: 2310230171 | D39: EG4015 | E39: 10.21.190.20 | F39: f8:2f:5b:04:d6:86 | G39: eGauge103612 | H39: owner | I39: Av3n9rLa | J39: WH-XF037 | K39: mara | L39: marawh | M39: Yes
A40: XF038 | B40: C074 / C075 | C40: 2502170193 | D40: EG4015 | E40: 10.21.200.20 | F40: f8:2f:5b:05:06:ea | G40: eGauge103584 | H40: owner | I40: eMhA2Vm5 | J40: WH-XF038 | K40: mara | L40: marawh | M40: Yes
...

Sheet IP Ranges - Air (OLD)
A1: VLAN ID | B1: Purpose | C1: Containers | D1: Netblock | E1: Gateway | F1: Size | G1: DHCP Range | H1: V1 | I1: V2 | J1: V3 | M1: IP Ranges
A2: 1 | B2: CN Internal | C2: SCADA | D2: 10.10.0.0 | E2: 10.10.0.254 | F2: /24 | G2: .200-.225
A3: =A2+1 -> 2 | B3: Antminer | C3: C246 | D3: 10.10.100.0 | E3: ="10.10."&A3&".254" -> 10.10.2.254 | F3: /24 | G3: .1-.250 | I3: C246 | M3: 10.10.100.0-254
A4: =A3+1 -> 3 | B4: Antminer | C4: C246 | D4: 10.10.101.0 | E4: ="10.10."&A4&".254" -> 10.10.3.254 | F4: /24 | G4: .1-.250 | J4: C246 | M4: 10.10.101.0-254
A5: =A4+1 -> 4 | B5: Whatsminer | C5: C252 | D5: 10.10.104.0 | E5: ="10.10."&A5&".254" -> 10.10.4.254 | F5: /24 | G5: .1-.250 | H5: C252 | M5: 10.10.104.0-254
A6: =A5+1 -> 5 | B6: Whatsminer | C6: C252 | D6: 10.10.105.0 | E6: ="10.10."&A6&".254" -> 10.10.5.254 | F6: /24 | G6: .1-.250 | I6: C252 | M6: 10.10.105.0-254
A7: =A6+1 -> 6 | B7: Whatsminer | C7: C252 | D7: 10.10.106.0 | E7: ="10.10."&A7&".254" -> 10.10.6.254 | F7: /24 | G7: .1-.250 | J7: C252 | M7: 10.10.106.0-254
A8: =A7+1 -> 7 | B8: Whatsminer | C8: C260 | D8: 10.10.111.0 | E8: ="10.10."&A8&".254" -> 10.10.7.254 | F8: /24 | G8: .1-.250 | H8: C260 | M8: 10.10.111.0-254
A9: =A8+1 -> 8 | B9: Whatsminer | C9: C263 | D9: 10.10.112.0 | E9: ="10.10."&A9&".254" -> 10.10.8.254 | F9: /24 | G9: .1-.250 | I9: C263 | M9: 10.10.112.0-254
A10: 9 | D10: 10.10.9.0 | E10: 10.10.9.254 | F10: /24 | G10: .1-.250
A11: 10 | D11: 10.10.10.0 | E11: ="10.10."&A11&".254" -> 10.10.10.254 | F11: /24 | G11: .1-.250
A12: =A11+1 -> 11 | D12: 10.10.11.0 | E12: ="10.10."&A12&".254" -> 10.10.11.254 | F12: /24 | G12: .1-.250
A13: =A12+1 -> 12 | D13: 10.10.12.0 | E13: ="10.10."&A13&".254" -> 10.10.12.254 | F13: /24 | G13: .1-.250
A14: =A13+1 -> 13 | D14: 10.10.13.0 | E14: ="10.10."&A14&".254" -> 10.10.13.254 | F14: /24 | G14: .1-.250
A15: =A14+1 -> 14 | D15: 10.10.14.0 | E15: ="10.10."&A15&".254" -> 10.10.14.254 | F15: /24 | G15: .1-.250
A16: =A15+1 -> 15 | D16: 10.10.15.0 | E16: ="10.10."&A16&".254" -> 10.10.15.254 | F16: /24 | G16: .1-.250
A17: =A16+1 -> 16 | D17: 10.10.16.0 | E17: ="10.10."&A17&".254" -> 10.10.16.254 | F17: /24 | G17: .1-.250
A18: =A17+1 -> 17 | D18: 10.10.17.0 | E18: ="10.10."&A18&".254" -> 10.10.17.254 | F18: /24 | G18: .1-.250
A19: =A18+1 -> 18 | D19: 10.10.18.0 | E19: ="10.10."&A19&".254" -> 10.10.18.254 | F19: /24 | G19: .1-.250
A20: =A19+1 -> 19 | D20: 10.10.19.0 | E20: ="10.10."&A20&".254" -> 10.10.19.254 | F20: /24 | G20: .1-.250
A21: =A20+1 -> 20 | D21: 10.10.20.0 | E21: ="10.10."&A21&".254" -> 10.10.20.254 | F21: /24 | G21: .1-.250
A22: =A21+1 -> 21 | D22: 10.10.21.0 | E22: ="10.10."&A22&".254" -> 10.10.21.254 | F22: /24 | G22: .1-.250
A23: =A22+1 -> 22 | D23: 10.10.22.0 | E23: ="10.10."&A23&".254" -> 10.10.22.254 | F23: /24 | G23: .1-.250
... A31: =A30+1 -> 30 | D31: 10.10.30.0 | E31: ="10.10."&A31&".254" -> 10.10.30.254 | F31: /24 | G31: .1-.250
A32: 255 | D32: 10.10.255.0 | E32: ="10.10."&A32&".254" -> 10.10.255.254 | F32: /24 | G32: .1-.250
A33: 256 | B33: No DHCP pool? | D33: 10.11.0.0 | E33: 10.11.0.254 | F33: /24 | G33: .1-.250
A34: 257 | D34: 10.11.1.0 | E34: ="10.11."&#REF!&".254" -> #REF! | F34: /24 | G34: .1-.250
A35: 258 | D35: 10.11.2.0 | E35: ="10.11."&#REF!&".254" -> #REF! | F35: /24 | G35: .1-.250
A36: 259 | D36: 10.11.3.0 | E36: ="10.11."&#REF!&".254" -> #REF! | F36: /24 | G36: .1-.250
A37: 260 | D37: 10.11.4.0 | E37: ="10.11."&#REF!&".254" -> #REF! | F37: /24 | G37: .1-.250
A38: 261 | D38: 10.11.5.0 | E38: ="10.11."&#REF!&".254" -> #REF! | F38: /24 | G38: .1-.250
A39: 262 | D39: 10.11.6.0 | E39: ="10.11."&#REF!&".254" -> #REF! | F39: /24 | G39: .1-.250
A40: 263 | D40: 10.11.7.0 | E40: ="10.11."&#REF!&".254" -> #REF! | F40: /24 | G40: .1-.250
A41: 264 | D41: 10.11.8.0 | E41: ="10.11."&#REF!&".254" -> #REF! | F41: /24 | G41: .1-.250
A42: 265 | D42: 10.11.9.0 | E42: ="10.11."&#REF!&".254" -> #REF! | F42: /24 | G42: .1-.250
A43: 266 | D43: 10.11.10.0 | E43: ="10.11."&#REF!&".254" -> #REF! | F43: /24 | G43: .1-.250
A44: 267 | D44: 10.11.11.0 | E44: ="10.11."&#REF!&".254" -> #REF! | F44: /24 | G44: .1-.250
A45: 268 | D45: 10.11.12.0 | E45: ="10.11."&#REF!&".254" -> #REF! | F45: /24 | G45: .1-.250
... A71: 294 | D71: 10.11.38.0 | E71: ="10.11."&#REF!&".254" -> #REF! | F71: /24 | G71: .1-.250
A72: =A71+1 -> 295 | B72: Antminer | C72: C225 | D72: 10.10.113.0 | E72: ="10.10."&A72&".254" -> 10.10.295.254 | F72: /24 | G72: .1-.250 | H72: C225 | M72: =D72&"-254" -> 10.10.113.0-254
...

Sheet Pivot Table 1
A1: COUNTA of Container
A2: 287
C3: 43 | E3: 3 Days | F3: CB - Open Disconnect
C6: 47 | E6: 3 Days | F6: CB - Open Disconnect
C9: 6 | E9: 1 Day | F9: Constellation Switchgear
C11: 17 | E11: 1 Day | F11: CB
C14: 15 | E14: 1 Day | F14: CB
C17: 16 | E17: 1 Day | F17: CB
C20: 17 | E20: 1 Day | F20: CB
C23: 2

Sheet Outage Plan
B1: MDC # | C1: Customer | D1: Substation Breaker Name (CN) | E1: Anticipated Outage Date
B2: C009 | C2: US Bitcoin Corp | D2: 11A | E2: 45092
B3: C010 | C3: US Bitcoin Corp | D3: 11A | E3: 45092
B4: C011 | C4: US Bitcoin Corp | D4: 11A | E4: 45092
B5: C012 | C5: US Bitcoin Corp | D5: 11A | E5: 45092
B6: C013 | C6: US Bitcoin Corp | D6: 11A | E6: 45092
B7: C014 | C7: US Bitcoin Corp | D7: 11A | E7: 45092
B8: C015 | D8: 11A | E8: 45092
B9: C016 | C9: US Bitcoin Corp | D9: 11A | E9: 45092
B10: C017 | D10: 11A | E10: 45092
B11: C018 | D11: 11A | E11: 45092
B12: C019 | C12: Compass Mining | D12: 11A | E12: 45092
B13: C020 | C13: Marathon Patent Group, Inc | D13: 11A | E13: 45092
B14: C132 | C14: US Bitcoin Corp | D14: 11B | E14: 45092
B15: C144 | C15: US Bitcoin Corp | D15: 11B | E15: 45092
B16: C145 | C16: US Bitcoin Corp | D16: 11B | E16: 45092
B17: C146 | C17: US Bitcoin Corp | D17: 11B | E17: 45092
B18: C147 | C18: US Bitcoin Corp | D18: 11B | E18: 45092
B19: C148 | C19: US Bitcoin Corp | D19: 11B | E19: 45092
B20: C149 | C20: US Bitcoin Corp | D20: 11B | E20: 45092
B21: C156 | C21: Sphere 3D | D21: 11B | E21: 45092
B22: C157 | D22: 11B | E22: 45092
B23: C158 | D23: 11B | E23: 45092
B24: C159 | C24: Integrated Ventures | D24: 11B | E24: 45092
B25: C160 | D25: 11B | E25: 45092
B26: C161 | D26: 11B | E26: 45092
B27: C162 | D27: 11B | E27: 45092
B28: C163 | D28: 11B | E28: 45092
B29: C120 | C29: Touzi Capital | D29: 11C | E29: 45092
B30: C133 | C30: US Bitcoin Corp | D30: 11C | E30: 45092
B31: C134 | C31: US Bitcoin Corp | D31: 11C | E31: 45092
B32: C135 | C32: US Bitcoin Corp | D32: 11C | E32: 45092
B33: C136 | C33: US Bitcoin Corp | D33: 11C | E33: 45092
B34: C137 | D34: 11C | E34: 45092
B35: C138 | C35: Compass Mining | D35: 11C | E35: 45092
B36: C139 | C36: Compass Mining | D36: 11C | E36: 45092
B37: C140 | D37: 11C | E37: 45092
B38: C141 | D38: 11C | E38: 45092
B39: C150 | C39: Compass Mining | D39: 11C | E39: 45092
B40: C151 | C40: Compass Mining | D40: 11C | E40: 45092
...

Sheet VLAN issues
B2: Container | C2: Issue
B3: C063 | C3: VLAN > 255
B4: C074 | C4: VLAN > 255
B5: C085 | C5: VLAN > 255
B6: C086 | C6: VLAN > 255
B7: C097 | C7: VLAN > 255
B8: C100 | C8: VLAN > 255
B9: C103 | C9: VLAN > 255
B10: C104 | C10: VLAN > 255
B11: C106 | C11: VLAN > 255
B12: C107 | C12: VLAN > 255
B13: C109 | C13: VLAN > 255
... B20: C119 | C20: VLAN > 255

Sheet Miner Types
A1: Model | B1: Ideal Hashrate (TH) | C1: Sticker Efficiency (W/TH) | D1: Power Consumption (W) | E1: Model | F1: Antminer S19 (86T) | G1: Antminer S19 (90T) | H1: Antminer S19 (95T) | I1: Antminer S19 Pro (105T) | J1: Antminer S19 Pro (110T) | K1: Antminer S19j Pro (100T) | L1: Antminer S19j Pro (104T) | M1: Antminer S19j Pro (88T) | N1: Antminer S19j Pro (92T) | O1: Antminer S19j Pro (96T) | P1: Antminer S19XP (134T) | Q1: Antminer S19XP (141T) | R1: Whatsminer M30S (82T) | S1: Whatsminer M30S (84T) | T1: Whatsminer M30S (86T) | U1: Whatsminer M30S (88T) | V1: Whatsminer M30S (90T) | W1: Whatsminer M30S (92T) | X1: Whatsminer M30S (94T) | Y1: Whatsminer M30S+ (100T) | Z1: Whatsminer M30S+ (102T) | AA1: Whatsminer M30S+ (104T) | AB1: Whatsminer M30S+ (96T) | AC1: Whatsminer M30S+ (98T) | AD1: Whatsminer M30S++ (104T) | AE1: Whatsminer M30S++ (106T) | AF1: Whatsminer M30S++ (108T) | AG1: Whatsminer M30S++ (110T) | AH1: Whatsminer M31S (74T)
A2: Antminer S19 (86T) | B2: 86 | C2: 34 | D2: =B2*C2 -> 2924 | E2: Ideal Hashrate (TH) | F2: 86 | G2: 90 | H2: 95 | I2: 105 | J2: 110 | K2: 100 | L2: 104 | M2: 88 | N2: 92 | O2: 96 | P2: 134 | Q2: 141 | R2: 82 | S2: 84 | T2: 86 | U2: 86 | V2: 90 | W2: 92 | X2: 94 | Y2: 100 | Z2: 102 | AA2: 104 | AB2: 96 | AC2: 98 | AD2: 104 | AE2: 106 | AF2: 108 | AG2: 110 | AH2: 74
A3: Antminer S19 (90T) | B3: 90 | C3: 34 | D3: =B3*C3 -> 3060 | E3: Sticker Efficiency (W/TH) | F3: 34 | G3: 34 | H3: 34 | I3: 29.5 | J3: 29.5 | K3: 29.5 | L3: 29.5 | M3: 29.5 | N3: 29.5 | O3: 29.5 | P3: 21.5 | Q3: 21.5 | R3: 38 | S3: 38 | T3: 38 | U3: 38 | V3: 38 | W3: 38 | X3: 38 | Y3: 34 | Z3: 34 | AA3: 34 | AB3: 34 | AC3: 34 | AD3: 31 | AE3: 31 | AF3: 31 | AG3: 31 | AH3: 44
A4: Antminer S19 (95T) | B4: 95 | C4: 34 | D4: =B4*C4 -> 3230 | E4: Power Consumption (W) | F4: =F2*F3 -> 2924 | G4: =G2*G3 -> 3060 | H4: =H2*H3 -> 3230 | I4: =I2*I3 -> 3097.5 | J4: =J2*J3 -> 3245 | K4: =K2*K3 -> 2950 | L4: =L2*L3 -> 3068 | M4: =M2*M3 -> 2596 | ... AH4: =AH2*AH3 -> 3256
A5: Antminer S19 Pro (105T) | B5: 105 | C5: 29.5 | D5: =B5*C5 -> 3097.5
A6: Antminer S19 Pro (110T) | B6: 110 | C6: 29.5 | D6: =B6*C6 -> 3245
A7: Antminer S19j Pro (100T) | B7: 100 | C7: 29.5 | D7: =B7*C7 -> 2950
A8: Antminer S19j Pro (104T) | B8: 104 | C8: 29.5 | D8: =B8*C8 -> 3068
A9: Antminer S19j Pro (88T) | B9: 88 | C9: 29.5 | D9: =B9*C9 -> 2596
A10: Antminer S19j Pro (92T) | B10: 92 | C10: 29.5 | D10: =B10*C10 -> 2714
A11: Antminer S19j Pro (96T) | B11: 96 | C11: 29.5 | D11: =B11*C11 -> 2832
A12: Antminer S19XP (134T) | B12: 134 | C12: 21.5 | D12: =B12*C12 -> 2881
A13: Antminer S19XP (141T) | B13: 141 | C13: 21.5 | D13: =B13*C13 -> 3031.5
A14: Whatsminer M30S (82T) | B14: 82 | C14: 38 | D14: =B14*C14 -> 3116
A15: Whatsminer M30S (84T) | B15: 84 | C15: 38 | D15: =B15*C15 -> 3192
A16: Whatsminer M30S (86T) | B16: 86 | C16: 38 | D16: =B16*C16 -> 3268
... A30: Whatsminer M31S (74T) | B30: 74 | C30: 44 | D30: =B30*C30 -> 3256

Sheet Labor
A1: Date | B1: 44575 | C1: 44582 | D1: 44589 | E1: 44596 | F1: 44603 | G1: 44610 | H1: 44617 | I1: 44624 | J1: 44631 | K1: 44638 | L1: 44645 | M1: 44652
A3: Energize | I3: =7*560 -> 3920 | K3: =7*560 -> 3920 | M3: =7*560 -> 3920
A4: Total Energized | I4: =I3+H4 -> 3920 | J4: =J3+I4 -> 3920 | K4: =K3+J4 -> 7840 | L4: =L3+K4 -> 7840 | M4: =M3+L4 -> 11760
A6: Delivery | F6: 6500 | G6: 3500 | L6: 1760
A7: Total Delivered | B7: =B6 -> 0 | F7: =E7+F6 -> 6500 | G7: =F7+G6 -> 10000 | H7: =G7+H6 -> 10000 | I7: =H7+I6 -> 10000 | J7: =I7+J6 -> 10000 | K7: =J7+K6 -> 10000 | L7: =K7+L6 -> 11760 | M7: =L7+M6 -> 11760
A14: Labor | B14: Hours | C14: Minutes
A15: Unboxing | B15: =C15/60 -> 0.05 | C15: 3
A16: Loading | B16: =C16/60 -> 0.083333333 | C16: 5
A19: Days/ Week | B19: 5
A20: Hours/ Day | B20: 7
A21: Hours/ Week | B21: =B19*B20 -> 35
B23: Week/ Worker | C23: Day/ Worker
A24: Unboxed | B24: =B21/B15 -> 700 | C24: =B20/B15 -> 140
A25: Loaded | B25: =B21/B16 -> 420 | C25: =B20/B16 -> 84
A27: Employee Max | B27: 10

Sheet Land Clearing
B1: Firm | C1: Acres | D1: Total Cost | E1: Price per Acre
B2: Pierce Land Clearing | C2: 10 | D2: 40000 | E2: =D2/C2 -> 4000
B3: Lozoya | C3: 12 | D3: 30472 | E3: =D3/C3 -> 2539.3333
B4: Williams Paving | C4: 10 | D4: 2,500 - 3,000 | E4: 2700

Sheet Geotech Survey
B1: Firm | C1: Phase 1 Cost | D1: Phase 2 | E1: Land Clearing Cost | F1: Total Cost
B2: Beyond | C2: 12000 | D2: 20000 | E2: TBD | F2: =SUM(C2:E2) -> 32000
B3: Terracon | C3: 13800 | D3: 18700 | E3: TBD | F3: 32500

Sheet Container Ratio
C1: Miners/Unit | D1: MW/Unit | E1: MW/Unit (M30s) | F1: $/Unit | G1: $/MW | H1: $/MW (M30s) | K1: Site
B2: Tessarack | C2: 968 | D2: 3.45 | E2: =C2*K4/1000000 -> 3.2912 | F2: 613000 | G2: =F2/D2 -> 177681.16 | H2: =F2/E2 -> 186254.25 | J2: Megawatts | K2: 42
B3: RK | C3: 560 | D3: 2 | E3: =C3*K4/1000000 -> 1.904 | F3: 315000 | G3: =F3/D3 -> 157500 | H3: =F3/E3 -> 165441.18 | K3: M30s
J4: Watts | K4: 3400
G6: MW Limit
A7: Option 1 | C7: Units | D7: Total Spots | E7: Total MW (M30s) | G7: Container | H7: Site | J7: Total $ | K7: $/Miner
B8: Tessarack | C8: 0 | D8: =C8*$C$2 -> 0 | E8: =$E$2*C8 -> 0 | G8: =C8*$D$2 -> 0 | H8: =E8 -> 0 | J8: =C8*$F$2 -> 0 | K8: =J8/D14 -> #DIV/0!
B9: RK | C9: 21 | D9: =C9*$C$3 -> 11760 | E9: =$E$3*C9 -> 39.984 | G9: =C9*$D$3 -> 42 | H9: =K2-E8 -> 42 | J9: =C9*$F$3 -> 6615000 | K9: =J9/D15 -> 562.5
B10: Total | C10: =C9+C8 -> 21 | D10: =D9+D8 -> 11760 | E10: =SUM(E8:E9) -> 39.984 | G10: =G9+G8 -> 42 | H10: =H9+H8 -> 42 | J10: =J9+J8 -> 6615000 | K10: =J10/D16 -> 562.5
G12: Underutilization
C13: MW Utilization | D13: Active Miners | G13: Container | H13: Site
B14: Tessarack | C14: =MIN(E8,G8,H8) -> 0 | D14: =C14*1000000/$K$4 -> 0 | G14: =D8-D14 -> 0
B15: RK | C15: =MIN(E9,G9,H9) -> 39.984 | D15: =C15*1000000/$K$4 -> 11760 | G15: =D9-D15 -> 0
B16: Total | C16: =MIN(E10,G10,H10) -> 39.984 | D16: =D14+D15 -> 11760 | G16: =D10-D16 -> 0 | H16: =K2*1000000/K4-D16 -> 592.94118
G18: MW Limit
A19: Option 2 | C19: Units | D19: Total Spots | E19: Total MW (M30s) | G19: Container | H19: Site | J19: Total $ | K19: $/Miner
B20: Tessarack | C20: 0 | D20: =C20*$C$2 -> 0 | E20: =$E$2*C20 -> 0 | G20: =C20*$D$2 -> 0 | H20: =E20 -> 0 | J20: =C20*$F$2 -> 0 | K20: =J20/D26 -> #DIV/0!
B21: RK | C21: 22 | D21: =C21*$C$3 -> 12320 | E21: =$E$3*C21 -> 41.888 | G21: =C21*$D$3 -> 44 | H21: =K2-E20 -> 42 | J21: =C21*$F$3 -> 6930000 | K21: =J21/D27 -> 562.5
B22: Total | C22: =C21+C20 -> 22 | D22: =D21+D20 -> 12320 | E22: =SUM(E20:E21) -> 41.888 | G22: =G21+G20 -> 44 | H22: =H21+H20 -> 42 | J22: =J21+J20 -> 6930000 | K22: =J22/D28 -> 562.5
G24: Underutilization
C25: MW Utilization | D25: Active Miners | G25: Container | H25: Site
B26: Tessarack | C26: =MIN(E20,G20,H20) -> 0 | D26: =C26*1000000/$K$4 -> 0 | G26: =D20-D26 -> 0
B27: RK | C27: =MIN(E21,G21,H21) -> 41.888 | D27: =C27*1000000/$K$4 -> 12320 | G27: =D21-D27 -> 0
B28: Total | C28: =MIN(E22,G22,H22) -> 41.888 | D28: =MIN(D26+D27,K2*1000000/K4) -> 12320 | G28: =D22-D28 -> 0 | H28: =K2*1000000/K4-D28 -> 32.941176
H30: $ | I30: Miners | J30: $/Miner | K30: $/Additional
B31: Assumptions: | G31: Option 1 | H31: =J10 -> 6615000 | I31: =D16 -> 11760 | J31: =K10 -> 562.5
B32: 1. Leaving an RK vacant is preferred to leaving a Tessarack vacant | G32: Option 2 | H32: =J22 -> 6930000 | I32: =D28 -> 12320 | J32: =K22 -> 562.5
B33: 2. Only cost is that of the containers. Cost of transformer could be added to $/Unit | G33: Difference | H33: =H31-H32 -> -315000 | I33: =I31-I32 -> -560 | J33: =J31-J32 -> 0 | K33: =H33/I33 -> 562.5

Sheet Sound Concern
B2: Container | C2: Risk Level
B3: C163 | C3: High
B4: C153 | C4: High
B5: C141 | C5: High
B6: C155 | C6: High
B7: C143 | C7: High
B8: C130 | C8: High
B9: C118 | C9: High
B10: C131 | C10: High
B11: C119 | C11: High
B12: C106 | C12: High
B13: C094 | C13: High
... B44: C034 | C44: Medium
